# üêõ Variable Scope Fix - click_time Not Defined

## Issue

**Error:** `name 'click_time' is not defined`

**Occurred after successful vote:**
```
[SUCCESS] ‚úÖ Vote VERIFIED successful: 12631 -> 12632 (+1)
[VOTE] Instance #1 vote failed: name 'click_time' is not defined
```

## Root Cause

Variables were defined inside the try block but referenced in the exception handler:

**Before:**
```python
async def attempt_vote(self):
    try:
        # ... code ...
        click_time = datetime.now()  # ‚ùå Defined here
        initial_count = await self.get_vote_count()
        # ... more code ...
    except Exception as e:
        # Try to use click_time here
        self.vote_logger.log_vote_attempt(
            time_of_click=click_time  # ‚ùå Not defined if exception before this!
        )
```

## Fix Applied

**After:**
```python
async def attempt_vote(self):
    # ‚úÖ Initialize at the start
    click_time = datetime.now()
    initial_count = None
    click_attempts = 0
    button_clicked = False
    
    try:
        # ... code ...
        # Update click_time at actual click moment
        click_time = datetime.now()
        # ... more code ...
    except Exception as e:
        # ‚úÖ Variables always defined!
        self.vote_logger.log_vote_attempt(
            time_of_click=click_time
        )
```

## Changes

1. ‚úÖ Moved variable initialization to start of method
2. ‚úÖ Variables now available in exception handler
3. ‚úÖ click_time updated at actual click moment
4. ‚úÖ Fallback values if exception occurs early

## Result

- ‚úÖ No more "name 'click_time' is not defined" errors
- ‚úÖ Exception handler can always log with valid data
- ‚úÖ Votes log correctly even if errors occur

## File Modified

`backend/voter_engine.py` - Fixed variable scope in `attempt_vote()` method

## Status

‚úÖ **Fixed** - All variables now properly scoped
